<?xml version="1.0" encoding="utf-8"?>
<robot name="dual_6dof">
  <link name="base_link">
    <inertial>
      <origin xyz="0.0 0.0 0.0" rpy="0.0 0.0 0.0"/>
      <mass value="10.0"/>
      <inertia ixx="0.5" ixy="0.0" ixz="0.0" iyy="0.5" iyz="0.0" izz="0.5"/>
    </inertial>
  </link>

  <!-- Left arm - 6 DOF -->
  <link name="left_link_1">
    <inertial>
      <origin xyz="0.0 0.03 0.12" rpy="0.0 0.0 0.0"/>
      <mass value="3.5"/>
      <inertia ixx="0.09" ixy="0.0" ixz="0.0" iyy="0.08" iyz="0.0" izz="0.018"/>
    </inertial>
  </link>
  <link name="left_link_2">
    <inertial>
      <origin xyz="0.0003 0.055 0.04" rpy="0.0 0.0 0.0"/>
      <mass value="3.2"/>
      <inertia ixx="0.045" ixy="0.0" ixz="0.0" iyy="0.016" iyz="0.0" izz="0.04"/>
    </inertial>
  </link>
  <link name="left_link_3">
    <inertial>
      <origin xyz="0.0 0.028 0.11" rpy="0.0 0.0 0.0"/>
      <mass value="2.8"/>
      <inertia ixx="0.07" ixy="0.0" ixz="0.0" iyy="0.065" iyz="0.0" izz="0.009"/>
    </inertial>
  </link>
  <link name="left_link_4">
    <inertial>
      <origin xyz="0.0 0.062 0.032" rpy="0.0 0.0 0.0"/>
      <mass value="2.4"/>
      <inertia ixx="0.027" ixy="0.0" ixz="0.0" iyy="0.009" iyz="0.0" izz="0.026"/>
    </inertial>
  </link>
  <link name="left_link_5">
    <inertial>
      <origin xyz="0.0001 0.02 0.07" rpy="0.0 0.0 0.0"/>
      <mass value="1.6"/>
      <inertia ixx="0.018" ixy="0.0" ixz="0.0" iyy="0.016" iyz="0.0" izz="0.0045"/>
    </inertial>
  </link>
  <link name="left_link_6">
    <inertial>
      <origin xyz="0.0 0.0005 0.0003" rpy="0.0 0.0 0.0"/>
      <mass value="1.2"/>
      <inertia ixx="0.004" ixy="0.0" ixz="0.0" iyy="0.003" iyz="0.0" izz="0.0038"/>
    </inertial>
  </link>

  <!-- Right arm - 6 DOF -->
  <link name="right_link_1">
    <inertial>
      <origin xyz="0.0 -0.03 0.12" rpy="0.0 0.0 0.0"/>
      <mass value="3.5"/>
      <inertia ixx="0.09" ixy="0.0" ixz="0.0" iyy="0.08" iyz="0.0" izz="0.018"/>
    </inertial>
  </link>
  <link name="right_link_2">
    <inertial>
      <origin xyz="0.0003 -0.055 0.04" rpy="0.0 0.0 0.0"/>
      <mass value="3.2"/>
      <inertia ixx="0.045" ixy="0.0" ixz="0.0" iyy="0.016" iyz="0.0" izz="0.04"/>
    </inertial>
  </link>
  <link name="right_link_3">
    <inertial>
      <origin xyz="0.0 -0.028 0.11" rpy="0.0 0.0 0.0"/>
      <mass value="2.8"/>
      <inertia ixx="0.07" ixy="0.0" ixz="0.0" iyy="0.065" iyz="0.0" izz="0.009"/>
    </inertial>
  </link>
  <link name="right_link_4">
    <inertial>
      <origin xyz="0.0 -0.062 0.032" rpy="0.0 0.0 0.0"/>
      <mass value="2.4"/>
      <inertia ixx="0.027" ixy="0.0" ixz="0.0" iyy="0.009" iyz="0.0" izz="0.026"/>
    </inertial>
  </link>
  <link name="right_link_5">
    <inertial>
      <origin xyz="0.0001 -0.02 0.07" rpy="0.0 0.0 0.0"/>
      <mass value="1.6"/>
      <inertia ixx="0.018" ixy="0.0" ixz="0.0" iyy="0.016" iyz="0.0" izz="0.0045"/>
    </inertial>
  </link>
  <link name="right_link_6">
    <inertial>
      <origin xyz="0.0 -0.0005 0.0003" rpy="0.0 0.0 0.0"/>
      <mass value="1.2"/>
      <inertia ixx="0.004" ixy="0.0" ixz="0.0" iyy="0.003" iyz="0.0" izz="0.0038"/>
    </inertial>
  </link>

  <!-- Left arm joints -->
  <joint name="left_joint_1" type="revolute">
    <parent link="base_link"/>
    <child link="left_link_1"/>
    <origin xyz="0.0 0.3 0.0" rpy="0.0 0.0 0.0"/>
    <axis xyz="0.0 0.0 1.0"/>
    <limit lower="-2.967" upper="2.967" effort="30.0" velocity="1.0"/>
  </joint>
  <joint name="left_joint_2" type="revolute">
    <parent link="left_link_1"/>
    <child link="left_link_2"/>
    <origin xyz="0.0 0.0 0.2" rpy="1.5708 0.0 3.1416"/>
    <axis xyz="0.0 0.0 1.0"/>
    <limit lower="-2.094" upper="2.094" effort="30.0" velocity="1.0"/>
  </joint>
  <joint name="left_joint_3" type="revolute">
    <parent link="left_link_2"/>
    <child link="left_link_3"/>
    <origin xyz="0.0 0.19 0.0" rpy="1.5708 0.0 3.1416"/>
    <axis xyz="0.0 0.0 1.0"/>
    <limit lower="-2.967" upper="2.967" effort="30.0" velocity="1.0"/>
  </joint>
  <joint name="left_joint_4" type="revolute">
    <parent link="left_link_3"/>
    <child link="left_link_4"/>
    <origin xyz="0.0 0.0 0.19" rpy="1.5708 0.0 0.0"/>
    <axis xyz="0.0 0.0 1.0"/>
    <limit lower="-2.094" upper="2.094" effort="30.0" velocity="1.0"/>
  </joint>
  <joint name="left_joint_5" type="revolute">
    <parent link="left_link_4"/>
    <child link="left_link_5"/>
    <origin xyz="0.0 0.17 0.0" rpy="1.5708 0.0 3.1416"/>
    <axis xyz="0.0 0.0 1.0"/>
    <limit lower="-2.967" upper="2.967" effort="25.0" velocity="1.0"/>
  </joint>
  <joint name="left_joint_6" type="revolute">
    <parent link="left_link_5"/>
    <child link="left_link_6"/>
    <origin xyz="0.0 0.0 0.18" rpy="1.5708 0.0 0.0"/>
    <axis xyz="0.0 0.0 1.0"/>
    <limit lower="-2.094" upper="2.094" effort="20.0" velocity="1.0"/>
  </joint>

  <!-- Right arm joints -->
  <joint name="right_joint_1" type="revolute">
    <parent link="base_link"/>
    <child link="right_link_1"/>
    <origin xyz="0.0 -0.3 0.0" rpy="0.0 0.0 0.0"/>
    <axis xyz="0.0 0.0 1.0"/>
    <limit lower="-2.967" upper="2.967" effort="30.0" velocity="1.0"/>
  </joint>
  <joint name="right_joint_2" type="revolute">
    <parent link="right_link_1"/>
    <child link="right_link_2"/>
    <origin xyz="0.0 0.0 0.2" rpy="1.5708 0.0 3.1416"/>
    <axis xyz="0.0 0.0 1.0"/>
    <limit lower="-2.094" upper="2.094" effort="30.0" velocity="1.0"/>
  </joint>
  <joint name="right_joint_3" type="revolute">
    <parent link="right_link_2"/>
    <child link="right_link_3"/>
    <origin xyz="0.0 -0.19 0.0" rpy="1.5708 0.0 3.1416"/>
    <axis xyz="0.0 0.0 1.0"/>
    <limit lower="-2.967" upper="2.967" effort="30.0" velocity="1.0"/>
  </joint>
  <joint name="right_joint_4" type="revolute">
    <parent link="right_link_3"/>
    <child link="right_link_4"/>
    <origin xyz="0.0 0.0 0.19" rpy="1.5708 0.0 0.0"/>
    <axis xyz="0.0 0.0 1.0"/>
    <limit lower="-2.094" upper="2.094" effort="30.0" velocity="1.0"/>
  </joint>
  <joint name="right_joint_5" type="revolute">
    <parent link="right_link_4"/>
    <child link="right_link_5"/>
    <origin xyz="0.0 -0.17 0.0" rpy="1.5708 0.0 3.1416"/>
    <axis xyz="0.0 0.0 1.0"/>
    <limit lower="-2.967" upper="2.967" effort="25.0" velocity="1.0"/>
  </joint>
  <joint name="right_joint_6" type="revolute">
    <parent link="right_link_5"/>
    <child link="right_link_6"/>
    <origin xyz="0.0 0.0 0.18" rpy="1.5708 0.0 0.0"/>
    <axis xyz="0.0 0.0 1.0"/>
    <limit lower="-2.094" upper="2.094" effort="20.0" velocity="1.0"/>
  </joint>
</robot>
