<?xml version="1.0" encoding="utf-8"?>
<robot name="tree_2_5_5">
  <link name="base_link">
    <inertial>
      <origin xyz="0.0 0.0 0.0" rpy="0.0 0.0 0.0"/>
      <mass value="8.0"/>
      <inertia ixx="0.4" ixy="0.0" ixz="0.0" iyy="0.4" iyz="0.0" izz="0.4"/>
    </inertial>
  </link>

  <!-- Base chain - 2 DOF -->
  <link name="trunk_link_1">
    <inertial>
      <origin xyz="0.0 0.0 0.1" rpy="0.0 0.0 0.0"/>
      <mass value="5.0"/>
      <inertia ixx="0.12" ixy="0.0" ixz="0.0" iyy="0.11" iyz="0.0" izz="0.022"/>
    </inertial>
  </link>
  <link name="trunk_link_2">
    <inertial>
      <origin xyz="0.0 0.0 0.12" rpy="0.0 0.0 0.0"/>
      <mass value="4.5"/>
      <inertia ixx="0.11" ixy="0.0" ixz="0.0" iyy="0.1" iyz="0.0" izz="0.02"/>
    </inertial>
  </link>

  <!-- Left branch - 5 DOF -->
  <link name="left_link_1">
    <inertial>
      <origin xyz="0.0 0.03 0.11" rpy="0.0 0.0 0.0"/>
      <mass value="3.2"/>
      <inertia ixx="0.08" ixy="0.0" ixz="0.0" iyy="0.075" iyz="0.0" izz="0.016"/>
    </inertial>
  </link>
  <link name="left_link_2">
    <inertial>
      <origin xyz="0.0 0.052 0.038" rpy="0.0 0.0 0.0"/>
      <mass value="2.8"/>
      <inertia ixx="0.042" ixy="0.0" ixz="0.0" iyy="0.015" iyz="0.0" izz="0.038"/>
    </inertial>
  </link>
  <link name="left_link_3">
    <inertial>
      <origin xyz="0.0 0.027 0.1" rpy="0.0 0.0 0.0"/>
      <mass value="2.4"/>
      <inertia ixx="0.065" ixy="0.0" ixz="0.0" iyy="0.06" iyz="0.0" izz="0.009"/>
    </inertial>
  </link>
  <link name="left_link_4">
    <inertial>
      <origin xyz="0.0 0.058 0.03" rpy="0.0 0.0 0.0"/>
      <mass value="2.0"/>
      <inertia ixx="0.024" ixy="0.0" ixz="0.0" iyy="0.008" iyz="0.0" izz="0.022"/>
    </inertial>
  </link>
  <link name="left_link_5">
    <inertial>
      <origin xyz="0.0 0.018 0.065" rpy="0.0 0.0 0.0"/>
      <mass value="1.4"/>
      <inertia ixx="0.015" ixy="0.0" ixz="0.0" iyy="0.014" iyz="0.0" izz="0.004"/>
    </inertial>
  </link>

  <!-- Right branch - 5 DOF -->
  <link name="right_link_1">
    <inertial>
      <origin xyz="0.0 -0.03 0.11" rpy="0.0 0.0 0.0"/>
      <mass value="3.2"/>
      <inertia ixx="0.08" ixy="0.0" ixz="0.0" iyy="0.075" iyz="0.0" izz="0.016"/>
    </inertial>
  </link>
  <link name="right_link_2">
    <inertial>
      <origin xyz="0.0 -0.052 0.038" rpy="0.0 0.0 0.0"/>
      <mass value="2.8"/>
      <inertia ixx="0.042" ixy="0.0" ixz="0.0" iyy="0.015" iyz="0.0" izz="0.038"/>
    </inertial>
  </link>
  <link name="right_link_3">
    <inertial>
      <origin xyz="0.0 -0.027 0.1" rpy="0.0 0.0 0.0"/>
      <mass value="2.4"/>
      <inertia ixx="0.065" ixy="0.0" ixz="0.0" iyy="0.06" iyz="0.0" izz="0.009"/>
    </inertial>
  </link>
  <link name="right_link_4">
    <inertial>
      <origin xyz="0.0 -0.058 0.03" rpy="0.0 0.0 0.0"/>
      <mass value="2.0"/>
      <inertia ixx="0.024" ixy="0.0" ixz="0.0" iyy="0.008" iyz="0.0" izz="0.022"/>
    </inertial>
  </link>
  <link name="right_link_5">
    <inertial>
      <origin xyz="0.0 -0.018 0.065" rpy="0.0 0.0 0.0"/>
      <mass value="1.4"/>
      <inertia ixx="0.015" ixy="0.0" ixz="0.0" iyy="0.014" iyz="0.0" izz="0.004"/>
    </inertial>
  </link>

  <!-- Base chain joints -->
  <joint name="trunk_joint_1" type="revolute">
    <parent link="base_link"/>
    <child link="trunk_link_1"/>
    <origin xyz="0.0 0.0 0.0" rpy="0.0 0.0 0.0"/>
    <axis xyz="0.0 0.0 1.0"/>
    <limit lower="-2.9" upper="2.9" effort="40.0" velocity="1.0"/>
  </joint>
  <joint name="trunk_joint_2" type="revolute">
    <parent link="trunk_link_1"/>
    <child link="trunk_link_2"/>
    <origin xyz="0.0 0.0 0.22" rpy="0.0 0.0 0.0"/>
    <axis xyz="0.0 0.0 1.0"/>
    <limit lower="-2.5" upper="2.5" effort="35.0" velocity="1.0"/>
  </joint>

  <!-- Left branch joints -->
  <joint name="left_joint_1" type="revolute">
    <parent link="trunk_link_2"/>
    <child link="left_link_1"/>
    <origin xyz="0.0 0.25 0.2" rpy="0.0 0.0 0.5236"/>
    <axis xyz="0.0 0.0 1.0"/>
    <limit lower="-2.8" upper="2.8" effort="30.0" velocity="1.0"/>
  </joint>
  <joint name="left_joint_2" type="revolute">
    <parent link="left_link_1"/>
    <child link="left_link_2"/>
    <origin xyz="0.0 0.0 0.19" rpy="1.5708 0.0 3.1416"/>
    <axis xyz="0.0 0.0 1.0"/>
    <limit lower="-2.0" upper="2.0" effort="28.0" velocity="1.0"/>
  </joint>
  <joint name="left_joint_3" type="revolute">
    <parent link="left_link_2"/>
    <child link="left_link_3"/>
    <origin xyz="0.0 0.18 0.0" rpy="1.5708 0.0 3.1416"/>
    <axis xyz="0.0 0.0 1.0"/>
    <limit lower="-2.7" upper="2.7" effort="25.0" velocity="1.0"/>
  </joint>
  <joint name="left_joint_4" type="revolute">
    <parent link="left_link_3"/>
    <child link="left_link_4"/>
    <origin xyz="0.0 0.0 0.17" rpy="1.5708 0.0 0.0"/>
    <axis xyz="0.0 0.0 1.0"/>
    <limit lower="-2.1" upper="2.1" effort="22.0" velocity="1.0"/>
  </joint>
  <joint name="left_joint_5" type="revolute">
    <parent link="left_link_4"/>
    <child link="left_link_5"/>
    <origin xyz="0.0 0.16 0.0" rpy="1.5708 0.0 3.1416"/>
    <axis xyz="0.0 0.0 1.0"/>
    <limit lower="-2.6" upper="2.6" effort="18.0" velocity="1.0"/>
  </joint>

  <!-- Right branch joints -->
  <joint name="right_joint_1" type="revolute">
    <parent link="trunk_link_2"/>
    <child link="right_link_1"/>
    <origin xyz="0.0 -0.25 0.2" rpy="0.0 0.0 -0.5236"/>
    <axis xyz="0.0 0.0 1.0"/>
    <limit lower="-2.8" upper="2.8" effort="30.0" velocity="1.0"/>
  </joint>
  <joint name="right_joint_2" type="revolute">
    <parent link="right_link_1"/>
    <child link="right_link_2"/>
    <origin xyz="0.0 0.0 0.19" rpy="1.5708 0.0 3.1416"/>
    <axis xyz="0.0 0.0 1.0"/>
    <limit lower="-2.0" upper="2.0" effort="28.0" velocity="1.0"/>
  </joint>
  <joint name="right_joint_3" type="revolute">
    <parent link="right_link_2"/>
    <child link="right_link_3"/>
    <origin xyz="0.0 -0.18 0.0" rpy="1.5708 0.0 3.1416"/>
    <axis xyz="0.0 0.0 1.0"/>
    <limit lower="-2.7" upper="2.7" effort="25.0" velocity="1.0"/>
  </joint>
  <joint name="right_joint_4" type="revolute">
    <parent link="right_link_3"/>
    <child link="right_link_4"/>
    <origin xyz="0.0 0.0 0.17" rpy="1.5708 0.0 0.0"/>
    <axis xyz="0.0 0.0 1.0"/>
    <limit lower="-2.1" upper="2.1" effort="22.0" velocity="1.0"/>
  </joint>
  <joint name="right_joint_5" type="revolute">
    <parent link="right_link_4"/>
    <child link="right_link_5"/>
    <origin xyz="0.0 -0.16 0.0" rpy="1.5708 0.0 3.1416"/>
    <axis xyz="0.0 0.0 1.0"/>
    <limit lower="-2.6" upper="2.6" effort="18.0" velocity="1.0"/>
  </joint>
</robot>
