<?xml version="1.0" encoding="utf-8"?>
<robot name="iiwa">
  <link name="world"/>
  <link name="lbr_iiwa_link_1">
    <inertial>
      <origin xyz="0.0 -0.03 0.12" rpy="0.0 0.0 0.0"/>
      <mass value="4.0"/>
      <inertia ixx="0.1" ixy="0.0" ixz="0.0" iyy="0.09000000000000001" iyz="0.0" izz="0.02"/>
    </inertial>
  </link>
  <link name="lbr_iiwa_link_2">
    <inertial>
      <origin xyz="0.0003 0.059 0.042" rpy="0.0 0.0 0.0"/>
      <mass value="4.0"/>
      <inertia ixx="0.05" ixy="0.0" ixz="0.0" iyy="0.018" iyz="0.0" izz="0.044"/>
    </inertial>
  </link>
  <joint name="lbr_iiwa_joint_1" type="revolute">
    <parent link="world"/>
    <child link="lbr_iiwa_link_1"/>
    <origin xyz="0.0 0.0 0.1575" rpy="0.0 -0.0 0.0"/>
    <axis xyz="0.0 0.0 1.0"/>
    <limit lower="-100000.0" upper="100000.0" effort="30.0" velocity="1.0"/>
  </joint>
  <joint name="lbr_iiwa_joint_2" type="revolute">
    <parent link="lbr_iiwa_link_1"/>
    <child link="lbr_iiwa_link_2"/>
    <origin xyz="0.0 0.0 0.2025" rpy="1.5707963705062866 -8.742278000372477e-8 3.1415926535897896"/>
    <axis xyz="0.0 0.0 1.0"/>
    <limit lower="-100000.0" upper="100000.0" effort="30.0" velocity="1.0"/>
  </joint>
</robot>


